Workbook

Sheet Point List
A1: Signal Type | B1: Tag No | C1: Name | D1: Instrument | E1: Status | F1: Data Type | G1: Memory Type | H1: PDU Hexadecimal | I1: Modbus Address | J1: Modicon Address | K1: Proface Type | L1: Proface Data Type | M1: Size (Bits) | N1: PLC Memory Address | O1: Position | P1: I/O Card Number | Q1: Channel | R1: I/O | S1: Global Variable | T1: Program Variable Name | U1: Operator Visiblity | V1: Deadman | W1: Validated
A2: Switch | B2: SW-0 | C2: Master_Switch | D2: SYSTEM | E2: IN-USE | F2: N/A | G2: N/A | H2: N/A | I2: N/A | J2: N/A | K2: N/A | M2: N/A | N2: N/A | O2: N/A | P2: N/A | Q2: N/A | R2: N/A | S2: N/A | T2: XXX | U2: YES | V2: NO | W2: TRUE
A3: Switch | B3: SW-1 | C3: System_Start | D3: SYSTEM | E3: IN-USE | F3: BOOL | G3: FLAG | H3: =_xlfn.CONCAT("0x",DEC2HEX(I3)) -> 0x3000 | I3: {=INDEX('Mapping Sheet'!B:B,'Mapping Sheet'!A1,1)} -> 12288 | J3: =_xlfn.CONCAT(0,I3+1) -> 012289 | K3: MOMENTARY | L3: BitAddress | M3: 1 | N3: =_xlfn.CONCAT("%MX",INDEX('Mapping Sheet'!E:E,Table1[[#This Row],[Modbus Address]]-12287,1),".",INDEX('Mapping Sheet'!F:F,Table1[[#This Row],[Modbus Address]]-12287,1)) -> %MX0.0 | O3: N/A | P3: N/A | Q3: N/A | R3: N/A | S3: NO | T3: =_xlfn.CONCAT("axSW[",AB1, "]") -> axSW[] | U3: YES | V3: NO | W3: TRUE
A4: Switch | B4: SW-2 | C4: System_Shutdown | D4: SYSTEM | E4: IN-USE | F4: BOOL | G4: FLAG | H4: =_xlfn.CONCAT("0x",DEC2HEX(I4)) -> 0x3001 | I4: =I3+1 -> 12289 | J4: =_xlfn.CONCAT(0,I4+1) -> 012290 | K4: MOMENTARY | L4: BitAddress | M4: 1 | N4: =_xlfn.CONCAT("%MX",INDEX('Mapping Sheet'!E:E,Table1[[#This Row],[Modbus Address]]-12287,1),".",INDEX('Mapping Sheet'!F:F,Table1[[#This Row],[Modbus Address]]-12287,1)) -> %MX0.1 | O4: N/A | P4: N/A | Q4: N/A | R4: N/A | S4: NO | T4: =_xlfn.CONCAT("axSW[",AB2, "]") -> axSW[] | U4: YES | V4: NO | W4: TRUE
A5: Switch | B5: SW-3 | C5: Simplex_Mode | D5: PUMP | E5: IN-USE | F5: BOOL | G5: FLAG | H5: =_xlfn.CONCAT("0x",DEC2HEX(I5)) -> 0x3002 | I5: =I4+1 -> 12290 | J5: =_xlfn.CONCAT(0,I5+1) -> 012291 | K5: MOMENTARY | L5: BitAddress | M5: 1 | N5: =_xlfn.CONCAT("%MX",INDEX('Mapping Sheet'!E:E,Table1[[#This Row],[Modbus Address]]-12287,1),".",INDEX('Mapping Sheet'!F:F,Table1[[#This Row],[Modbus Address]]-12287,1)) -> %MX0.2 | O5: N/A | P5: N/A | Q5: N/A | R5: N/A | S5: NO | T5: =_xlfn.CONCAT("axSW[",AB3, "]") -> axSW[] | U5: YES | V5: NO | W5: TRUE
A6: Switch | B6: SW-4 | C6: Manual_Turnover | D6: PUMP | E6: IN-USE | F6: BOOL | G6: FLAG | H6: =_xlfn.CONCAT("0x",DEC2HEX(I6)) -> 0x3003 | I6: =I5+1 -> 12291 | J6: =_xlfn.CONCAT(0,I6+1) -> 012292 | K6: MOMENTARY | L6: BitAddress | M6: 1 | N6: =_xlfn.CONCAT("%MX",INDEX('Mapping Sheet'!E:E,Table1[[#This Row],[Modbus Address]]-12287,1),".",INDEX('Mapping Sheet'!F:F,Table1[[#This Row],[Modbus Address]]-12287,1)) -> %MX0.3 | O6: N/A | P6: N/A | Q6: N/A | R6: N/A | S6: NO | T6: =_xlfn.CONCAT("axSW[",AB4, "]") -> axSW[] | U6: YES | V6: NO | W6: TRUE
A7: Switch | B7: SW-5 | C7: Enable_Manual_Valve_Control | D7: VALVE | E7: IN-USE | F7: BOOL | G7: FLAG | H7: =_xlfn.CONCAT("0x",DEC2HEX(I7)) -> 0x3004 | I7: =I6+1 -> 12292 | J7: =_xlfn.CONCAT(0,I7+1) -> 012293 | K7: BIT INVERT | L7: BitAddress | M7: 1 | N7: =_xlfn.CONCAT("%MX",INDEX('Mapping Sheet'!E:E,Table1[[#This Row],[Modbus Address]]-12287,1),".",INDEX('Mapping Sheet'!F:F,Table1[[#This Row],[Modbus Address]]-12287,1)) -> %MX0.4 | O7: N/A | P7: N/A | Q7: N/A | R7: N/A | S7: NO | T7: =_xlfn.CONCAT("axSW[",AB5, "]") -> axSW[] | U7: YES | V7: YES | W7: FALSE
A8: Switch | B8: SW-6 | C8: Enable_Manual_Fan_Control | D8: FAN | E8: IN-USE | F8: BOOL | G8: FLAG | H8: =_xlfn.CONCAT("0x",DEC2HEX(I8)) -> 0x3005 | I8: =I7+1 -> 12293 | J8: =_xlfn.CONCAT(0,I8+1) -> 012294 | K8: BIT INVERT | L8: BitAddress | M8: 1 | N8: =_xlfn.CONCAT("%MX",INDEX('Mapping Sheet'!E:E,Table1[[#This Row],[Modbus Address]]-12287,1),".",INDEX('Mapping Sheet'!F:F,Table1[[#This Row],[Modbus Address]]-12287,1)) -> %MX0.5 | O8: N/A | P8: N/A | Q8: N/A | R8: N/A | S8: NO | T8: =_xlfn.CONCAT("axSW[",AB6, "]") -> axSW[] | U8: YES | V8: YES | W8: TRUE
A9: Switch | B9: SW-7 | C9: AVAILABLE | D9: N/A | E9: DEPRECATED | F9: BOOL | G9: FLAG | H9: =_xlfn.CONCAT("0x",DEC2HEX(I9)) -> 0x3006 | I9: =I8+1 -> 12294 | J9: =_xlfn.CONCAT(0,I9+1) -> 012295 | K9: N/A | L9: BitAddress | M9: 1 | N9: =_xlfn.CONCAT("%MX",INDEX('Mapping Sheet'!E:E,Table1[[#This Row],[Modbus Address]]-12287,1),".",INDEX('Mapping Sheet'!F:F,Table1[[#This Row],[Modbus Address]]-12287,1)) -> %MX0.6 | O9: N/A | P9: N/A | Q9: N/A | R9: N/A | S9: NO | T9: =_xlfn.CONCAT("axSW[",AB7, "]") -> axSW[] | U9: YES | V9: NO | W9: FALSE
A10: Switch | B10: SW-8 | C10: Force_Fan_1_On_Off | D10: FAN | E10: IN-USE | F10: BOOL | G10: FLAG | H10: =_xlfn.CONCAT("0x",DEC2HEX(I10)) -> 0x3007 | I10: =I9+1 -> 12295 | J10: =_xlfn.CONCAT(0,I10+1) -> 012296 | K10: BIT INVERT | L10: BitAddress | M10: 1 | N10: =_xlfn.CONCAT("%MX",INDEX('Mapping Sheet'!E:E,Table1[[#This Row],[Modbus Address]]-12287,1),".",INDEX('Mapping Sheet'!F:F,Table1[[#This Row],[Modbus Address]]-12287,1)) -> %MX0.7 | O10: N/A | P10: N/A | Q10: N/A | R10: N/A | S10: NO | T10: =_xlfn.CONCAT("axSW[",AB8, "]") -> axSW[] | U10: YES | V10: NO | W10: TRUE
A11: Switch | B11: SW-9 | C11: Force_Fan_2_On_Off | D11: FAN | E11: IN-USE | F11: BOOL | G11: FLAG | H11: =_xlfn.CONCAT("0x",DEC2HEX(I11)) -> 0x3008 | I11: =I10+1 -> 12296 | J11: =_xlfn.CONCAT(0,I11+1) -> 012297 | K11: BIT INVERT | L11: BitAddress | M11: 1 | N11: =_xlfn.CONCAT("%MX",INDEX('Mapping Sheet'!E:E,Table1[[#This Row],[Modbus Address]]-12287,1),".",INDEX('Mapping Sheet'!F:F,Table1[[#This Row],[Modbus Address]]-12287,1)) -> %MX0.8 | O11: N/A | P11: N/A | Q11: N/A | R11: N/A | S11: NO | T11: =_xlfn.CONCAT("axSW[",AB9, "]") -> axSW[] | U11: YES | V11: NO | W11: TRUE
A12: Switch | B12: SW-10 | C12: Primary_Hydraulic_Fault_ACK | D12: PUMP, FLOW, PRESSURE | E12: IN-USE | F12: BOOL | G12: FLAG | H12: =_xlfn.CONCAT("0x",DEC2HEX(I12)) -> 0x3009 | I12: =I11+1 -> 12297 | J12: =_xlfn.CONCAT(0,I12+1) -> 012298 | K12: MOMENTARY | L12: BitAddress | M12: 1 | N12: =_xlfn.CONCAT("%MX",INDEX('Mapping Sheet'!E:E,Table1[[#This Row],[Modbus Address]]-12287,1),".",INDEX('Mapping Sheet'!F:F,Table1[[#This Row],[Modbus Address]]-12287,1)) -> %MX0.9 | O12: N/A | P12: N/A | Q12: N/A | R12: N/A | S12: NO | T12: =_xlfn.CONCAT("axSW[",AB10, "]") -> axSW[] | U12: YES | V12: NO | W12: FALSE
A13: Switch | B13: SW-11 | C13: Secondary_Hydraulic_Fault_ACK | D13: PUMP, FLOW, PRESSURE | E13: IN-USE | F13: BOOL | G13: FLAG | H13: =_xlfn.CONCAT("0x",DEC2HEX(I13)) -> 0x300A | I13: =I12+1 -> 12298 | J13: =_xlfn.CONCAT(0,I13+1) -> 012299 | K13: MOMENTARY | L13: BitAddress | M13: 1 | N13: =_xlfn.CONCAT("%MX",INDEX('Mapping Sheet'!E:E,Table1[[#This Row],[Modbus Address]]-12287,1),".",INDEX('Mapping Sheet'!F:F,Table1[[#This Row],[Modbus Address]]-12287,1)) -> %MX0.10 | O13: N/A | P13: N/A | Q13: N/A | R13: N/A | S13: NO | T13: =_xlfn.CONCAT("axSW[",AB11, "]") -> axSW[] | U13: YES | V13: NO | W13: FALSE
A14: Switch | B14: SW-12 | C14: Enable_Pump_Cycling | D14: PUMP | E14: IN-USE | F14: BOOL | G14: FLAG | H14: =_xlfn.CONCAT("0x",DEC2HEX(I14)) -> 0x300B | I14: =I13+1 -> 12299 | J14: =_xlfn.CONCAT(0,I14+1) -> 012300 | K14: MOMENTARY | L14: BitAddress | M14: 1 | N14: =_xlfn.CONCAT("%MX",INDEX('Mapping Sheet'!E:E,Table1[[#This Row],[Modbus Address]]-12287,1),".",INDEX('Mapping Sheet'!F:F,Table1[[#This Row],[Modbus Address]]-12287,1)) -> %MX0.11 | O14: N/A | P14: N/A | Q14: N/A | R14: N/A | S14: NO | T14: =_xlfn.CONCAT("axSW[",AB12, "]") -> axSW[] | U14: YES | V14: NO | W14: FALSE
A15: Switch | B15: SW-13 | C15: Reset_Pump_Differential_Signal | D15: PUMP | E15: IN-USE | F15: BOOL | G15: FLAG | H15: =_xlfn.CONCAT("0x",DEC2HEX(I15)) -> 0x300C | I15: =I14+1 -> 12300 | J15: =_xlfn.CONCAT(0,I15+1) -> 012301 | K15: MOMENTARY | L15: BitAddress | M15: 1 | N15: =_xlfn.CONCAT("%MX",INDEX('Mapping Sheet'!E:E,Table1[[#This Row],[Modbus Address]]-12287,1),".",INDEX('Mapping Sheet'!F:F,Table1[[#This Row],[Modbus Address]]-12287,1)) -> %MX0.12 | O15: N/A | P15: N/A | Q15: N/A | R15: N/A | S15: NO | T15: =_xlfn.CONCAT("axSW[",AB13, "]") -> axSW[] | U15: YES | V15: NO | W15: FALSE
A16: Switch | B16: SW-14 | C16: Fault_ACK | D16: SYSTEM | E16: IN-USE | F16: BOOL | G16: FLAG | H16: =_xlfn.CONCAT("0x",DEC2HEX(I16)) -> 0x300D | I16: =I15+1 -> 12301 | J16: =_xlfn.CONCAT(0,I16+1) -> 012302 | K16: MOMENTARY | L16: BitAddress | M16: 1 | N16: =_xlfn.CONCAT("%MX",INDEX('Mapping Sheet'!E:E,Table1[[#This Row],[Modbus Address]]-12287,1),".",INDEX('Mapping Sheet'!F:F,Table1[[#This Row],[Modbus Address]]-12287,1)) -> %MX0.13 | O16: N/A | P16: N/A | Q16: N/A | R16: N/A | S16: NO | T16: =_xlfn.CONCAT("axSW[",AB14, "]") -> axSW[] | U16: YES | V16: NO | W16: FALSE
A17: Switch | B17: SW-15 | C17: AVAILABLE | E17: DEPRECATED | F17: BOOL | G17: FLAG | H17: =_xlfn.CONCAT("0x",DEC2HEX(I17)) -> 0x300E | I17: =I16+1 -> 12302 | J17: =_xlfn.CONCAT(0,I17+1) -> 012303 | K17: N/A | M17: 1 | N17: =_xlfn.CONCAT("%MX",INDEX('Mapping Sheet'!E:E,Table1[[#This Row],[Modbus Address]]-12287,1),".",INDEX('Mapping Sheet'!F:F,Table1[[#This Row],[Modbus Address]]-12287,1)) -> %MX0.14 | O17: N/A | P17: N/A | Q17: N/A | R17: N/A | S17: NO | T17: =_xlfn.CONCAT("axSW[",AB15, "]") -> axSW[] | U17: YES | V17: NO | W17: FALSE
A18: Switch | B18: SW-16 | C18: AVAILABLE | E18: DEPRECATED | F18: BOOL | G18: FLAG | H18: =_xlfn.CONCAT("0x",DEC2HEX(I18)) -> 0x300F | I18: =I17+1 -> 12303 | J18: =_xlfn.CONCAT(0,I18+1) -> 012304 | K18: N/A | M18: 1 | N18: =_xlfn.CONCAT("%MX",INDEX('Mapping Sheet'!E:E,Table1[[#This Row],[Modbus Address]]-12287,1),".",INDEX('Mapping Sheet'!F:F,Table1[[#This Row],[Modbus Address]]-12287,1)) -> %MX0.15 | O18: N/A | P18: N/A | Q18: N/A | R18: N/A | S18: NO | T18: =_xlfn.CONCAT("axSW[",AB16, "]") -> axSW[] | U18: YES | V18: NO | W18: FALSE
A19: Internal | B19: SIG-1 | C19: System_On | D19: SYSTEM | E19: IN-USE | F19: BOOL | G19: FLAG | H19: =_xlfn.CONCAT("0x",DEC2HEX(I19)) -> 0x3010 | I19: =I18+1 -> 12304 | J19: =_xlfn.CONCAT(0,I19+1) -> 012305 | K19: LAMP | L19: BitAddress | M19: 1 | N19: =_xlfn.CONCAT("%MX",INDEX('Mapping Sheet'!E:E,Table1[[#This Row],[Modbus Address]]-12287,1),".",INDEX('Mapping Sheet'!F:F,Table1[[#This Row],[Modbus Address]]-12287,1)) -> %MX1.0 | O19: N/A | P19: N/A | Q19: N/A | R19: N/A | S19: NO | T19: =_xlfn.CONCAT("axSIG[",AB1,"]") -> axSIG[] | U19: YES | V19: N/A | W19: FALSE
A20: Internal | B20: SIG-2 | C20: System_Shutting_Down | D20: SYSTEM | E20: IN-USE | F20: BOOL | G20: FLAG | H20: =_xlfn.CONCAT("0x",DEC2HEX(I20)) -> 0x3011 | I20: =I19+1 -> 12305 | J20: =_xlfn.CONCAT(0,I20+1) -> 012306 | K20: LAMP | L20: BitAddress | M20: 1 | N20: =_xlfn.CONCAT("%MX",INDEX('Mapping Sheet'!E:E,Table1[[#This Row],[Modbus Address]]-12287,1),".",INDEX('Mapping Sheet'!F:F,Table1[[#This Row],[Modbus Address]]-12287,1)) -> %MX1.1 | O20: N/A | P20: N/A | Q20: N/A | R20: N/A | S20: NO | T20: =_xlfn.CONCAT("axSIG[",AB2,"]") -> axSIG[] | U20: YES | V20: N/A | W20: FALSE
A21: Internal | B21: SIG-3 | C21: System_Initializing | D21: SYSTEM | E21: IN-USE | F21: BOOL | G21: FLAG | H21: =_xlfn.CONCAT("0x",DEC2HEX(I21)) -> 0x3012 | I21: =I20+1 -> 12306 | J21: =_xlfn.CONCAT(0,I21+1) -> 012307 | K21: LAMP | L21: BitAddress | M21: 1 | N21: =_xlfn.CONCAT("%MX",INDEX('Mapping Sheet'!E:E,Table1[[#This Row],[Modbus Address]]-12287,1),".",INDEX('Mapping Sheet'!F:F,Table1[[#This Row],[Modbus Address]]-12287,1)) -> %MX1.2 | O21: N/A | P21: N/A | Q21: N/A | R21: N/A | S21: NO | T21: =_xlfn.CONCAT("axSIG[",AB3,"]") -> axSIG[] | U21: YES | V21: N/A | W21: FALSE
A22: Internal | B22: SIG-4 | C22: System_Calibrating | D22: SYSTEM | E22: IN-USE | F22: BOOL | G22: FLAG | H22: =_xlfn.CONCAT("0x",DEC2HEX(I22)) -> 0x3013 | I22: =I21+1 -> 12307 | J22: =_xlfn.CONCAT(0,I22+1) -> 012308 | K22: LAMP | L22: BitAddress | M22: 1 | N22: =_xlfn.CONCAT("%MX",INDEX('Mapping Sheet'!E:E,Table1[[#This Row],[Modbus Address]]-12287,1),".",INDEX('Mapping Sheet'!F:F,Table1[[#This Row],[Modbus Address]]-12287,1)) -> %MX1.3 | O22: N/A | P22: N/A | Q22: N/A | R22: N/A | S22: NO | T22: =_xlfn.CONCAT("axSIG[",AB4,"]") -> axSIG[] | U22: YES | V22: N/A | W22: FALSE
A23: Internal | B23: SIG-5 | C23: Measured_Pump_Power | D23: PUMP | E23: IN-USE | F23: REAL | G23: FLAG | H23: =_xlfn.CONCAT("0x",DEC2HEX(I23)) -> 0x310C | I23: =I50+100 -> 12556 | J23: =_xlfn.CONCAT(4,I23+1) -> 412557 | K23: NUMERIC | L23: WordAddress | M23: 32 | N23: =_xlfn.CONCAT("%MD",INDEX('Mapping Sheet'!G:G,Table1[[#This Row],[Modbus Address]]-12287,1)) -> %MD134 | O23: N/A | P23: N/A | Q23: N/A | R23: N/A | S23: NO | T23: =_xlfn.CONCAT("arSW[",AB1,"]") -> arSW[] | U23: YES | V23: N/A | W23: FALSE
A24: Internal | B24: SIG-6 | C24: MICT | D24: RTD | E24: IN-USE | F24: REAL | G24: FLAG | H24: =_xlfn.CONCAT("0x",DEC2HEX(I24)) -> 0x310E | I24: =I23+2 -> 12558 | J24: =_xlfn.CONCAT(4,I24+1) -> 412559 | K24: NUMERIC | L24: WordAddress | M24: 32 | N24: =_xlfn.CONCAT("%MD",INDEX('Mapping Sheet'!G:G,Table1[[#This Row],[Modbus Address]]-12287,1)) -> %MD135 | O24: N/A | P24: N/A | Q24: N/A | R24: N/A | S24: NO | T24: =_xlfn.CONCAT("arSW[",AB2,"]") -> arSW[] | U24: YES | V24: N/A | W24: FALSE
A25: Internal | B25: SIG-7 | C25: Measured_Conductivity | D25: CONDUCTIVITY | E25: IN-USE | F25: REAL | G25: FLAG | H25: =_xlfn.CONCAT("0x",DEC2HEX(I25)) -> 0x3110 | I25: =I24+2 -> 12560 | J25: =_xlfn.CONCAT(4,I25+1) -> 412561 | K25: NUMERIC | L25: WordAddress | M25: 32 | N25: =_xlfn.CONCAT("%MD",INDEX('Mapping Sheet'!G:G,Table1[[#This Row],[Modbus Address]]-12287,1)) -> %MD136 | O25: N/A | P25: N/A | Q25: N/A | R25: N/A | S25: NO | T25: =_xlfn.CONCAT("arSW[",AB3,"]") -> arSW[] | U25: YES | V25: N/A | W25: FALSE
A26: Internal | B26: SIG-8 | C26: Measured_Flow | D26: FLOW | E26: IN-USE | F26: REAL | G26: FLAG | H26: =_xlfn.CONCAT("0x",DEC2HEX(I26)) -> 0x3112 | I26: =I25+2 -> 12562 | J26: =_xlfn.CONCAT(4,I26+1) -> 412563 | K26: NUMERIC | L26: WordAddress | M26: 32 | N26: =_xlfn.CONCAT("%MD",INDEX('Mapping Sheet'!G:G,Table1[[#This Row],[Modbus Address]]-12287,1)) -> %MD137 | O26: N/A | P26: N/A | Q26: N/A | R26: N/A | S26: NO | T26: =_xlfn.CONCAT("arSW[",AB4,"]") -> arSW[] | U26: YES | V26: N/A | W26: FALSE
A27: Internal | B27: SIG-9 | C27: Valve_Open_Percentage | D27: VALVE | E27: IN-USE | F27: REAL | G27: FLAG | H27: =_xlfn.CONCAT("0x",DEC2HEX(I27)) -> 0x3114 | I27: =I26+2 -> 12564 | J27: =_xlfn.CONCAT(4,I27+1) -> 412565 | K27: NUMERIC | L27: WordAddress | M27: 32 | N27: =_xlfn.CONCAT("%MD",INDEX('Mapping Sheet'!G:G,Table1[[#This Row],[Modbus Address]]-12287,1)) -> %MD138 | O27: N/A | P27: N/A | Q27: N/A | R27: N/A | S27: NO | T27: =_xlfn.CONCAT("arSW[",AB5,"]") -> arSW[] | U27: YES | V27: N/A | W27: FALSE
A28: Internal | B28: SIG-10 | C28: Real_RTD_1_Signal | D28: RTD | E28: IN-USE | F28: REAL | G28: FLAG | H28: =_xlfn.CONCAT("0x",DEC2HEX(I28)) -> 0x3116 | I28: =I27+2 -> 12566 | J28: =_xlfn.CONCAT(4,I28+1) -> 412567 | K28: NUMERIC | L28: WordAddress | M28: 32 | N28: =_xlfn.CONCAT("%MD",INDEX('Mapping Sheet'!G:G,Table1[[#This Row],[Modbus Address]]-12287,1)) -> %MD139 | O28: N/A | P28: N/A | Q28: N/A | R28: N/A | S28: NO | T28: =_xlfn.CONCAT("arSW[",AB6,"]") -> arSW[] | U28: NO | V28: N/A | W28: FALSE
A29: Internal | B29: SIG-11 | C29: Real_RTD_2_Signal | D29: RTD | E29: IN-USE | F29: REAL | G29: FLAG | H29: =_xlfn.CONCAT("0x",DEC2HEX(I29)) -> 0x3118 | I29: =I28+2 -> 12568 | J29: =_xlfn.CONCAT(4,I29+1) -> 412569 | K29: NUMERIC | L29: WordAddress | M29: 32 | N29: =_xlfn.CONCAT("%MD",INDEX('Mapping Sheet'!G:G,Table1[[#This Row],[Modbus Address]]-12287,1)) -> %MD140 | O29: N/A | P29: N/A | Q29: N/A | R29: N/A | S29: NO | T29: =_xlfn.CONCAT("arSW[",AB7,"]") -> arSW[] | U29: NO | V29: N/A | W29: FALSE
A30: Internal | B30: SIG-12 | C30: Real_RTD_3_Signal | D30: RTD | E30: IN-USE | F30: REAL | G30: FLAG | H30: =_xlfn.CONCAT("0x",DEC2HEX(I30)) -> 0x311A | I30: =I29+2 -> 12570 | J30: =_xlfn.CONCAT(4,I30+1) -> 412571 | K30: NUMERIC | L30: WordAddress | M30: 32 | N30: =_xlfn.CONCAT("%MD",INDEX('Mapping Sheet'!G:G,Table1[[#This Row],[Modbus Address]]-12287,1)) -> %MD141 | O30: N/A | P30: N/A | Q30: N/A | R30: N/A | S30: NO | T30: =_xlfn.CONCAT("arSW[",AB8,"]") -> arSW[] | U30: NO | V30: N/A | W30: FALSE
A31: Internal | B31: SIG-13 | C31: AVAILABLE | E31: DEPRECATED | F31: REAL | G31: FLAG | H31: =_xlfn.CONCAT("0x",DEC2HEX(I31)) -> 0x311C | I31: =I30+2 -> 12572 | J31: =_xlfn.CONCAT(4,I31+1) -> 412573 | K31: NUMERIC | L31: WordAddress | M31: 32 | N31: =_xlfn.CONCAT("%MD",INDEX('Mapping Sheet'!G:G,Table1[[#This Row],[Modbus Address]]-12287,1)) -> %MD142 | O31: N/A | P31: N/A | Q31: N/A | R31: N/A | S31: NO | T31: =_xlfn.CONCAT("arSW[",AB9,"]") -> arSW[] | U31: YES | V31: N/A | W31: FALSE
A32: Internal | B32: SIG-14 | C32: Measured_Valve_Position_ | D32: VALVE | E32: IN-USE | F32: REAL | G32: FLAG | H32: =_xlfn.CONCAT("0x",DEC2HEX(I32)) -> 0x311E | I32: =I31+2 -> 12574 | J32: =_xlfn.CONCAT(4,I32+1) -> 412575 | K32: NUMERIC | L32: WordAddress | M32: 32 | N32: =_xlfn.CONCAT("%MD",INDEX('Mapping Sheet'!G:G,Table1[[#This Row],[Modbus Address]]-12287,1)) -> %MD143 | O32: N/A | P32: N/A | Q32: N/A | R32: N/A | S32: NO | T32: =_xlfn.CONCAT("arSW[",AB10,"]") -> arSW[] | U32: YES | V32: N/A | W32: FALSE
A33: Internal | B33: SIG-15 | C33: Debounced_Water_Level_Low_Signal | D33: LEVEL | E33: RESERVED | F33: BOOL | G33: FLAG | H33: =_xlfn.CONCAT("0x",DEC2HEX(I33)) -> 0x3014 | I33: =I22+1 -> 12308 | J33: =_xlfn.CONCAT(0,I33+1) -> 012309 | K33: N/A | L33: WordAddress | M33: 1 | N33: =_xlfn.CONCAT("%MX",INDEX('Mapping Sheet'!E:E,Table1[[#This Row],[Modbus Address]]-12287,1),".",INDEX('Mapping Sheet'!F:F,Table1[[#This Row],[Modbus Address]]-12287,1)) -> %MX1.4 | O33: N/A | P33: N/A | Q33: N/A | R33: N/A | S33: NO | T33: =_xlfn.CONCAT("axSIG[",AB5,"]") -> axSIG[] | U33: NO | V33: N/A | W33: FALSE
A34: Internal | B34: SIG-16 | C34: Debounced_Water_Level_L_L_Signal | D34: LEVEL | E34: RESERVED | F34: BOOL | G34: FLAG | H34: =_xlfn.CONCAT("0x",DEC2HEX(I34)) -> 0x3015 | I34: =I33+1 -> 12309 | J34: =_xlfn.CONCAT(0,I34+1) -> 012310 | K34: N/A | M34: 1 | N34: =_xlfn.CONCAT("%MX",INDEX('Mapping Sheet'!E:E,Table1[[#This Row],[Modbus Address]]-12287,1),".",INDEX('Mapping Sheet'!F:F,Table1[[#This Row],[Modbus Address]]-12287,1)) -> %MX1.5 | O34: N/A | P34: N/A | Q34: N/A | R34: N/A | S34: NO | T34: =_xlfn.CONCAT("axSIG[",AB6,"]") -> axSIG[] | U34: NO | V34: N/A | W34: FALSE
A35: Internal | B35: SIG-17 | C35: Debounced_Pressure_Signal | D35: PRESSURE | E35: RESERVED | F35: BOOL | G35: FLAG | H35: =_xlfn.CONCAT("0x",DEC2HEX(I35)) -> 0x3016 | I35: =I34+1 -> 12310 | J35: =_xlfn.CONCAT(0,I35+1) -> 012311 | K35: N/A | M35: 1 | N35: =_xlfn.CONCAT("%MX",INDEX('Mapping Sheet'!E:E,Table1[[#This Row],[Modbus Address]]-12287,1),".",INDEX('Mapping Sheet'!F:F,Table1[[#This Row],[Modbus Address]]-12287,1)) -> %MX1.6 | O35: N/A | P35: N/A | Q35: N/A | R35: N/A | S35: NO | T35: =_xlfn.CONCAT("axSIG[",AB7,"]") -> axSIG[] | U35: NO | V35: N/A | W35: FALSE
A36: Internal | B36: SIG-18 | C36: Debounced_Conductivity_Alarm_Signal | D36: CONDUCTIVITY | E36: RESERVED | F36: BOOL | G36: FLAG | H36: =_xlfn.CONCAT("0x",DEC2HEX(I36)) -> 0x3017 | I36: =I35+1 -> 12311 | J36: =_xlfn.CONCAT(0,I36+1) -> 012312 | K36: N/A | M36: 1 | N36: =_xlfn.CONCAT("%MX",INDEX('Mapping Sheet'!E:E,Table1[[#This Row],[Modbus Address]]-12287,1),".",INDEX('Mapping Sheet'!F:F,Table1[[#This Row],[Modbus Address]]-12287,1)) -> %MX1.7 | O36: N/A | P36: N/A | Q36: N/A | R36: N/A | S36: NO | T36: =_xlfn.CONCAT("axSIG[",AB8,"]") -> axSIG[] | U36: NO | V36: N/A | W36: FALSE
A37: Internal | B37: SIG-19 | C37: Debounced_Conductivity_Fault_Signal | D37: CONDUCTIVITY | E37: RESERVED | F37: BOOL | G37: FLAG | H37: =_xlfn.CONCAT("0x",DEC2HEX(I37)) -> 0x3018 | I37: =I36+1 -> 12312 | J37: =_xlfn.CONCAT(0,I37+1) -> 012313 | K37: N/A | M37: 1 | N37: =_xlfn.CONCAT("%MX",INDEX('Mapping Sheet'!E:E,Table1[[#This Row],[Modbus Address]]-12287,1),".",INDEX('Mapping Sheet'!F:F,Table1[[#This Row],[Modbus Address]]-12287,1)) -> %MX1.8 | O37: N/A | P37: N/A | Q37: N/A | R37: N/A | S37: NO | T37: =_xlfn.CONCAT("axSIG[",AB9,"]") -> axSIG[] | U37: NO | V37: N/A | W37: FALSE
A38: Internal | B38: SIG-20 | C38: Output_Water_Level_Low_Signal | D38: LEVEL | E38: RESERVED | F38: BOOL | G38: FLAG | H38: =_xlfn.CONCAT("0x",DEC2HEX(I38)) -> 0x3019 | I38: =I37+1 -> 12313 | J38: =_xlfn.CONCAT(0,I38+1) -> 012314 | K38: LAMP | L38: BitAddress | M38: 1 | N38: =_xlfn.CONCAT("%MX",INDEX('Mapping Sheet'!E:E,Table1[[#This Row],[Modbus Address]]-12287,1),".",INDEX('Mapping Sheet'!F:F,Table1[[#This Row],[Modbus Address]]-12287,1)) -> %MX1.9 | O38: N/A | P38: N/A | Q38: N/A | R38: N/A | S38: NO | T38: =_xlfn.CONCAT("axSIG[",AB10,"]") -> axSIG[] | U38: YES | V38: N/A | W38: FALSE
A39: Internal | B39: SIG-21 | C39: Output_Water_Level_Low_Low | D39: LEVEL | E39: RESERVED | F39: BOOL | G39: FLAG | H39: =_xlfn.CONCAT("0x",DEC2HEX(I39)) -> 0x301A | I39: =I38+1 -> 12314 | J39: =_xlfn.CONCAT(0,I39+1) -> 012315 | K39: LAMP | L39: BitAddress | M39: 1 | N39: =_xlfn.CONCAT("%MX",INDEX('Mapping Sheet'!E:E,Table1[[#This Row],[Modbus Address]]-12287,1),".",INDEX('Mapping Sheet'!F:F,Table1[[#This Row],[Modbus Address]]-12287,1)) -> %MX1.10 | O39: N/A | P39: N/A | Q39: N/A | R39: N/A | S39: NO | T39: =_xlfn.CONCAT("axSIG[",AB11,"]") -> axSIG[] | U39: YES | V39: N/A | W39: FALSE
A40: Internal | B40: SIG-22 | C40: Output_Pressure_Signal | D40: PRESSURE | E40: RESERVED | F40: BOOL | G40: FLAG | H40: =_xlfn.CONCAT("0x",DEC2HEX(I40)) -> 0x301B | I40: =I39+1 -> 12315 | J40: =_xlfn.CONCAT(0,I40+1) -> 012316 | K40: LAMP | L40: BitAddress | M40: 1 | N40: =_xlfn.CONCAT("%MX",INDEX('Mapping Sheet'!E:E,Table1[[#This Row],[Modbus Address]]-12287,1),".",INDEX('Mapping Sheet'!F:F,Table1[[#This Row],[Modbus Address]]-12287,1)) -> %MX1.11 | O40: N/A | P40: N/A | Q40: N/A | R40: N/A | S40: NO | T40: =_xlfn.CONCAT("axSIG[",AB12,"]") -> axSIG[] | U40: YES | V40: N/A | W40: FALSE
...

Sheet Symbol Table
A1: GP-Pro EX | K1: =A1 -> GP-Pro EX
A2: File Type | B2: SymbolVariable | K2: =_xlfn.CONCAT(A2,",",B2) -> File Type,SymbolVariable
A3: File Version | B3: 3 | C3: 0 | K3: =_xlfn.CONCAT(A3,",",B3,",",C3) -> File Version,3,0
A5: Name | B5: Index | C5: Type | D5: External/Internal | E5: Address | F5: Keep | G5: Comment | K5: =_xlfn.CONCAT(A5,",",B5,",",C5,",",D5,",",E5,",",F5,",",G5) -> Name,Index,Type,External/Internal,Address,Keep,Comment
A6: ='Point List'!C3 -> System_Start | C6: ='Point List'!L3 -> BitAddress | D6: PLC1 | E6: ='Point List'!J3 -> 012289 | K6: =_xlfn.CONCAT(A6,",",B6,",",C6,",",D6,",",E6,",",F6,",",G6) -> System_Start,,BitAddress,PLC1,012289,,
A7: ='Point List'!C4 -> System_Shutdown | C7: ='Point List'!L4 -> BitAddress | D7: PLC1 | E7: ='Point List'!J4 -> 012290 | K7: =_xlfn.CONCAT(A7,",",B7,",",C7,",",D7,",",E7,",",F7,",",G7) -> System_Shutdown,,BitAddress,PLC1,012290,,
A8: ='Point List'!C5 -> Simplex_Mode | C8: ='Point List'!L5 -> BitAddress | D8: PLC1 | E8: ='Point List'!J5 -> 012291 | K8: =_xlfn.CONCAT(A8,",",B8,",",C8,",",D8,",",E8,",",F8,",",G8) -> Simplex_Mode,,BitAddress,PLC1,012291,,
A9: ='Point List'!C6 -> Manual_Turnover | C9: ='Point List'!L6 -> BitAddress | D9: PLC1 | E9: ='Point List'!J6 -> 012292 | K9: =_xlfn.CONCAT(A9,",",B9,",",C9,",",D9,",",E9,",",F9,",",G9) -> Manual_Turnover,,BitAddress,PLC1,012292,,
A10: ='Point List'!C7 -> Enable_Manual_Valve_Control | C10: ='Point List'!L7 -> BitAddress | D10: PLC1 | E10: ='Point List'!J7 -> 012293 | K10: =_xlfn.CONCAT(A10,",",B10,",",C10,",",D10,",",E10,",",F10,",",G10) -> Enable_Manual_Valve_Control,,BitAddress,PLC1,012293,,
A11: ='Point List'!C8 -> Enable_Manual_Fan_Control | C11: ='Point List'!L8 -> BitAddress | D11: PLC1 | E11: ='Point List'!J8 -> 012294 | K11: =_xlfn.CONCAT(A11,",",B11,",",C11,",",D11,",",E11,",",F11,",",G11) -> Enable_Manual_Fan_Control,,BitAddress,PLC1,012294,,
A12: ='Point List'!C9 -> AVAILABLE | C12: ='Point List'!L9 -> BitAddress | D12: PLC1 | E12: ='Point List'!J9 -> 012295 | K12: =_xlfn.CONCAT(A12,",",B12,",",C12,",",D12,",",E12,",",F12,",",G12) -> AVAILABLE,,BitAddress,PLC1,012295,,
A13: ='Point List'!C10 -> Force_Fan_1_On_Off | C13: ='Point List'!L10 -> BitAddress | D13: PLC1 | E13: ='Point List'!J10 -> 012296 | K13: =_xlfn.CONCAT(A13,",",B13,",",C13,",",D13,",",E13,",",F13,",",G13) -> Force_Fan_1_On_Off,,BitAddress,PLC1,012296,,
A14: ='Point List'!C11 -> Force_Fan_2_On_Off | C14: ='Point List'!L11 -> BitAddress | D14: PLC1 | E14: ='Point List'!J11 -> 012297 | K14: =_xlfn.CONCAT(A14,",",B14,",",C14,",",D14,",",E14,",",F14,",",G14) -> Force_Fan_2_On_Off,,BitAddress,PLC1,012297,,
A15: ='Point List'!C12 -> Primary_Hydraulic_Fault_ACK | C15: ='Point List'!L12 -> BitAddress | D15: PLC1 | E15: ='Point List'!J12 -> 012298 | K15: =_xlfn.CONCAT(A15,",",B15,",",C15,",",D15,",",E15,",",F15,",",G15) -> Primary_Hydraulic_Fault_ACK,,BitAddress,PLC1,012298,,
A16: ='Point List'!C13 -> Secondary_Hydraulic_Fault_ACK | C16: ='Point List'!L13 -> BitAddress | D16: PLC1 | E16: ='Point List'!J13 -> 012299 | K16: =_xlfn.CONCAT(A16,",",B16,",",C16,",",D16,",",E16,",",F16,",",G16) -> Secondary_Hydraulic_Fault_ACK,,BitAddress,PLC1,012299,,
A17: ='Point List'!C14 -> Enable_Pump_Cycling | C17: ='Point List'!L14 -> BitAddress | D17: PLC1 | E17: ='Point List'!J14 -> 012300 | K17: =_xlfn.CONCAT(A17,",",B17,",",C17,",",D17,",",E17,",",F17,",",G17) -> Enable_Pump_Cycling,,BitAddress,PLC1,012300,,
... A107: ='Point List'!C104 -> System_Diagnostics | C107: ='Point List'!L104 -> BitAddress | D107: PLC1 | E107: ='Point List'!J104 -> 012352 | K107: =_xlfn.CONCAT(A107,",",B107,",",C107,",",D107,",",E107,",",F107,",",G107) -> System_Diagnostics,,BitAddress,PLC1,012352,,
A108: ='Point List'!C105 -> Status_Indicator_Text | C108: ='Point List'!L105 -> WordAddress | D108: PLC1 | E108: ='Point List'!J105 -> 412683
A109: ='Point List'!C106 -> 0 | C109: ='Point List'!L106 -> 0 | D109: PLC1 | E109: ='Point List'!J106 -> 0
A110: ='Point List'!C107 -> 0 | C110: ='Point List'!L107 -> 0 | D110: PLC1 | E110: ='Point List'!J107 -> 0
A111: ='Point List'!C108 -> 0 | C111: ='Point List'!L108 -> 0 | D111: PLC1 | E111: ='Point List'!J108 -> 0
A112: ='Point List'!C109 -> 0 | C112: ='Point List'!L109 -> 0 | D112: PLC1 | E112: ='Point List'!J109 -> 0
A113: ='Point List'!C110 -> 0 | C113: ='Point List'!L110 -> 0 | D113: PLC1 | E113: ='Point List'!J110 -> 0
A114: ='Point List'!C111 -> 0 | C114: ='Point List'!L111 -> 0 | D114: PLC1 | E114: ='Point List'!J111 -> 0
A115: ='Point List'!C112 -> 0 | C115: ='Point List'!L112 -> 0 | D115: PLC1 | E115: ='Point List'!J112 -> 0
A116: ='Point List'!C113 -> 0 | C116: ='Point List'!L113 -> 0 | D116: PLC1 | E116: ='Point List'!J113 -> 0
A117: ='Point List'!C114 -> 0 | C117: ='Point List'!L114 -> 0 | D117: PLC1 | E117: ='Point List'!J114 -> 0
A118: ='Point List'!C115 -> 0 | C118: ='Point List'!L115 -> 0 | D118: PLC1 | E118: ='Point List'!J115 -> 0
A119: ='Point List'!C116 -> 0 | C119: ='Point List'!L116 -> 0 | D119: PLC1 | E119: ='Point List'!J116 -> 0
... A194: ='Point List'!C191 -> 0 | C194: ='Point List'!L191 -> 0 | D194: PLC1 | E194: ='Point List'!J191 -> 0

Sheet Mapping Sheet
A1: 1 | B1: 12288 | C1: =B1+1 -> 12289 | D1: =_xlfn.CONCAT("0x",DEC2HEX(B1)) -> 0x3000 | E1: 0 | F1: 0 | G1: 0
A2: 2 | B2: =B1+1 -> 12289 | C2: =B2+1 -> 12290 | D2: =_xlfn.CONCAT("0x",DEC2HEX(B2)) -> 0x3001 | E2: 0 | F2: 1
A3: =A2+1 -> 3 | B3: =B2+1 -> 12290 | C3: =B3+1 -> 12291 | D3: =_xlfn.CONCAT("0x",DEC2HEX(B3)) -> 0x3002 | E3: 0 | F3: 2 | G3: =G1+1 -> 1
A4: =A3+1 -> 4 | B4: =B3+1 -> 12291 | C4: =B4+1 -> 12292 | D4: =_xlfn.CONCAT("0x",DEC2HEX(B4)) -> 0x3003 | E4: 0 | F4: 3
A5: =A4+1 -> 5 | B5: =B4+1 -> 12292 | C5: =B5+1 -> 12293 | D5: =_xlfn.CONCAT("0x",DEC2HEX(B5)) -> 0x3004 | E5: 0 | F5: 4 | G5: =G3+1 -> 2
A6: =A5+1 -> 6 | B6: =B5+1 -> 12293 | C6: =B6+1 -> 12294 | D6: =_xlfn.CONCAT("0x",DEC2HEX(B6)) -> 0x3005 | E6: 0 | F6: 5
A7: =A6+1 -> 7 | B7: =B6+1 -> 12294 | C7: =B7+1 -> 12295 | D7: =_xlfn.CONCAT("0x",DEC2HEX(B7)) -> 0x3006 | E7: 0 | F7: 6 | G7: =G5+1 -> 3
A8: =A7+1 -> 8 | B8: =B7+1 -> 12295 | C8: =B8+1 -> 12296 | D8: =_xlfn.CONCAT("0x",DEC2HEX(B8)) -> 0x3007 | E8: 0 | F8: 7
A9: =A8+1 -> 9 | B9: =B8+1 -> 12296 | C9: =B9+1 -> 12297 | D9: =_xlfn.CONCAT("0x",DEC2HEX(B9)) -> 0x3008 | E9: 0 | F9: =F8+1 -> 8 | G9: =G7+1 -> 4
A10: =A9+1 -> 10 | B10: =B9+1 -> 12297 | C10: =B10+1 -> 12298 | D10: =_xlfn.CONCAT("0x",DEC2HEX(B10)) -> 0x3009 | E10: 0 | F10: =F9+1 -> 9
A11: =A10+1 -> 11 | B11: =B10+1 -> 12298 | C11: =B11+1 -> 12299 | D11: =_xlfn.CONCAT("0x",DEC2HEX(B11)) -> 0x300A | E11: 0 | F11: =F10+1 -> 10 | G11: =G9+1 -> 5
A12: =A11+1 -> 12 | B12: =B11+1 -> 12299 | C12: =B12+1 -> 12300 | D12: =_xlfn.CONCAT("0x",DEC2HEX(B12)) -> 0x300B | E12: 0 | F12: =F11+1 -> 11
A13: =A12+1 -> 13 | B13: =B12+1 -> 12300 | C13: =B13+1 -> 12301 | D13: =_xlfn.CONCAT("0x",DEC2HEX(B13)) -> 0x300C | E13: 0 | F13: =F12+1 -> 12 | G13: =G11+1 -> 6
A14: =A13+1 -> 14 | B14: =B13+1 -> 12301 | C14: =B14+1 -> 12302 | D14: =_xlfn.CONCAT("0x",DEC2HEX(B14)) -> 0x300D | E14: 0 | F14: =F13+1 -> 13
A15: =A14+1 -> 15 | B15: =B14+1 -> 12302 | C15: =B15+1 -> 12303 | D15: =_xlfn.CONCAT("0x",DEC2HEX(B15)) -> 0x300E | E15: 0 | F15: =F14+1 -> 14 | G15: =G13+1 -> 7
A16: =A15+1 -> 16 | B16: =B15+1 -> 12303 | C16: =B16+1 -> 12304 | D16: =_xlfn.CONCAT("0x",DEC2HEX(B16)) -> 0x300F | E16: 0 | F16: =F15+1 -> 15
A17: =A16+1 -> 17 | B17: =B16+1 -> 12304 | C17: =B17+1 -> 12305 | D17: =_xlfn.CONCAT("0x",DEC2HEX(B17)) -> 0x3010 | E17: =E1+1 -> 1 | F17: 0 | G17: =G15+1 -> 8
A18: =A17+1 -> 18 | B18: =B17+1 -> 12305 | C18: =B18+1 -> 12306 | D18: =_xlfn.CONCAT("0x",DEC2HEX(B18)) -> 0x3011 | E18: =E2+1 -> 1 | F18: 1
A19: =A18+1 -> 19 | B19: =B18+1 -> 12306 | C19: =B19+1 -> 12307 | D19: =_xlfn.CONCAT("0x",DEC2HEX(B19)) -> 0x3012 | E19: =E3+1 -> 1 | F19: 2 | G19: =G17+1 -> 9
A20: =A19+1 -> 20 | B20: =B19+1 -> 12307 | C20: =B20+1 -> 12308 | D20: =_xlfn.CONCAT("0x",DEC2HEX(B20)) -> 0x3013 | E20: =E4+1 -> 1 | F20: 3
A21: =A20+1 -> 21 | B21: =B20+1 -> 12308 | C21: =B21+1 -> 12309 | D21: =_xlfn.CONCAT("0x",DEC2HEX(B21)) -> 0x3014 | E21: =E5+1 -> 1 | F21: 4 | G21: =G19+1 -> 10
A22: =A21+1 -> 22 | B22: =B21+1 -> 12309 | C22: =B22+1 -> 12310 | D22: =_xlfn.CONCAT("0x",DEC2HEX(B22)) -> 0x3015 | E22: =E6+1 -> 1 | F22: 5
A23: =A22+1 -> 23 | B23: =B22+1 -> 12310 | C23: =B23+1 -> 12311 | D23: =_xlfn.CONCAT("0x",DEC2HEX(B23)) -> 0x3016 | E23: =E7+1 -> 1 | F23: 6 | G23: =G21+1 -> 11
A24: =A23+1 -> 24 | B24: =B23+1 -> 12311 | C24: =B24+1 -> 12312 | D24: =_xlfn.CONCAT("0x",DEC2HEX(B24)) -> 0x3017 | E24: =E8+1 -> 1 | F24: 7
A25: =A24+1 -> 25 | B25: =B24+1 -> 12312 | C25: =B25+1 -> 12313 | D25: =_xlfn.CONCAT("0x",DEC2HEX(B25)) -> 0x3018 | E25: =E9+1 -> 1 | F25: =F24+1 -> 8 | G25: =G23+1 -> 12
A26: =A25+1 -> 26 | B26: =B25+1 -> 12313 | C26: =B26+1 -> 12314 | D26: =_xlfn.CONCAT("0x",DEC2HEX(B26)) -> 0x3019 | E26: =E10+1 -> 1 | F26: =F25+1 -> 9
A27: =A26+1 -> 27 | B27: =B26+1 -> 12314 | C27: =B27+1 -> 12315 | D27: =_xlfn.CONCAT("0x",DEC2HEX(B27)) -> 0x301A | E27: =E11+1 -> 1 | F27: =F26+1 -> 10 | G27: =G25+1 -> 13
A28: =A27+1 -> 28 | B28: =B27+1 -> 12315 | C28: =B28+1 -> 12316 | D28: =_xlfn.CONCAT("0x",DEC2HEX(B28)) -> 0x301B | E28: =E12+1 -> 1 | F28: =F27+1 -> 11
A29: =A28+1 -> 29 | B29: =B28+1 -> 12316 | C29: =B29+1 -> 12317 | D29: =_xlfn.CONCAT("0x",DEC2HEX(B29)) -> 0x301C | E29: =E13+1 -> 1 | F29: =F28+1 -> 12 | G29: =G27+1 -> 14
A30: =A29+1 -> 30 | B30: =B29+1 -> 12317 | C30: =B30+1 -> 12318 | D30: =_xlfn.CONCAT("0x",DEC2HEX(B30)) -> 0x301D | E30: =E14+1 -> 1 | F30: =F29+1 -> 13
A31: =A30+1 -> 31 | B31: =B30+1 -> 12318 | C31: =B31+1 -> 12319 | D31: =_xlfn.CONCAT("0x",DEC2HEX(B31)) -> 0x301E | E31: =E15+1 -> 1 | F31: =F30+1 -> 14 | G31: =G29+1 -> 15
A32: =A31+1 -> 32 | B32: =B31+1 -> 12319 | C32: =B32+1 -> 12320 | D32: =_xlfn.CONCAT("0x",DEC2HEX(B32)) -> 0x301F | E32: =E16+1 -> 1 | F32: =F31+1 -> 15
A33: =A32+1 -> 33 | B33: =B32+1 -> 12320 | C33: =B33+1 -> 12321 | D33: =_xlfn.CONCAT("0x",DEC2HEX(B33)) -> 0x3020 | E33: =E17+1 -> 2 | F33: 0 | G33: =G31+1 -> 16
A34: =A33+1 -> 34 | B34: =B33+1 -> 12321 | C34: =B34+1 -> 12322 | D34: =_xlfn.CONCAT("0x",DEC2HEX(B34)) -> 0x3021 | E34: =E18+1 -> 2 | F34: 1
A35: =A34+1 -> 35 | B35: =B34+1 -> 12322 | C35: =B35+1 -> 12323 | D35: =_xlfn.CONCAT("0x",DEC2HEX(B35)) -> 0x3022 | E35: =E19+1 -> 2 | F35: 2 | G35: =G33+1 -> 17
A36: =A35+1 -> 36 | B36: =B35+1 -> 12323 | C36: =B36+1 -> 12324 | D36: =_xlfn.CONCAT("0x",DEC2HEX(B36)) -> 0x3023 | E36: =E20+1 -> 2 | F36: 3
A37: =A36+1 -> 37 | B37: =B36+1 -> 12324 | C37: =B37+1 -> 12325 | D37: =_xlfn.CONCAT("0x",DEC2HEX(B37)) -> 0x3024 | E37: =E21+1 -> 2 | F37: 4 | G37: =G35+1 -> 18
A38: =A37+1 -> 38 | B38: =B37+1 -> 12325 | C38: =B38+1 -> 12326 | D38: =_xlfn.CONCAT("0x",DEC2HEX(B38)) -> 0x3025 | E38: =E22+1 -> 2 | F38: 5
A39: =A38+1 -> 39 | B39: =B38+1 -> 12326 | C39: =B39+1 -> 12327 | D39: =_xlfn.CONCAT("0x",DEC2HEX(B39)) -> 0x3026 | E39: =E23+1 -> 2 | F39: 6 | G39: =G37+1 -> 19
A40: =A39+1 -> 40 | B40: =B39+1 -> 12327 | C40: =B40+1 -> 12328 | D40: =_xlfn.CONCAT("0x",DEC2HEX(B40)) -> 0x3027 | E40: =E24+1 -> 2 | F40: 7
...

Sheet SymbolTableCSV
A1: GP-Pro EX | K1: ="""" & A1 & """" -> "GP-Pro EX" | O1: "GP-Pro EX"
A2: File Type | B2: SymbolVariable | K2: =_xlfn.CONCAT(""""&A2&"""",",",""""&B2&"""") -> "File Type","SymbolVariable" | O2: "File Type","SymbolVariable"
A3: File Version | B3: 3 | C3: 0 | K3: =_xlfn.CONCAT(""""&A3&"""",",",""""&B3&"""",",",""""&C3&"""") -> "File Version","3","0" | O3: "File Version","3","0"
A5: Name | B5: Index | C5: Type | D5: Internal/External | E5: Address | F5: Keep | G5: Comment | K5: =_xlfn.CONCAT(""""&A5&"""",",",""""&B5&"""",",",""""&C5&"""",",",""""&D5&"""",",",""""&E5&"""",",",""""&F5&"""",",",""""&G5&"""") -> "Name","Index","Type","Internal/External","Address","Keep","Comment" | O5: "Name","Index","Type","External/Internal","Address","Keep","Comment"
A6: ='Point List'!C3 -> System_Start | C6: ='Point List'!L3 -> BitAddress | D6: PLC1 | E6: ='Point List'!J3 -> 012289 | K6: =_xlfn.CONCAT(A6,",",B6,",",C6,",",D6,",",E6,",",F6,",",G6) -> System_Start,,BitAddress,PLC1,012289,, | O6: System Start,,BitAddress,PLC1,012289,,
A7: ='Point List'!C4 -> System_Shutdown | C7: ='Point List'!L4 -> BitAddress | D7: PLC1 | E7: ='Point List'!J4 -> 012290 | K7: =_xlfn.CONCAT(A7,",",B7,",",C7,",",D7,",",E7,",",F7,",",G7) -> System_Shutdown,,BitAddress,PLC1,012290,, | O7: System Shutdown,,BitAddress,PLC1,012290,,
A8: ='Point List'!C5 -> Simplex_Mode | C8: ='Point List'!L5 -> BitAddress | D8: PLC1 | E8: ='Point List'!J5 -> 012291 | K8: =_xlfn.CONCAT(A8,",",B8,",",C8,",",D8,",",E8,",",F8,",",G8) -> Simplex_Mode,,BitAddress,PLC1,012291,, | O8: Simplex Mode,,BitAddress,PLC1,012291,,
A9: ='Point List'!C6 -> Manual_Turnover | C9: ='Point List'!L6 -> BitAddress | D9: PLC1 | E9: ='Point List'!J6 -> 012292 | K9: =_xlfn.CONCAT(A9,",",B9,",",C9,",",D9,",",E9,",",F9,",",G9) -> Manual_Turnover,,BitAddress,PLC1,012292,, | O9: Manual Turnover,,BitAddress,PLC1,012292,,
A10: ='Point List'!C7 -> Enable_Manual_Valve_Control | C10: ='Point List'!L7 -> BitAddress | D10: PLC1 | E10: ='Point List'!J7 -> 012293 | K10: =_xlfn.CONCAT(A10,",",B10,",",C10,",",D10,",",E10,",",F10,",",G10) -> Enable_Manual_Valve_Control,,BitAddress,PLC1,012293,, | O10: Enable Manual Valve Control,,BitAddress,PLC1,012293,,
A11: ='Point List'!C8 -> Enable_Manual_Fan_Control | C11: ='Point List'!L8 -> BitAddress | D11: PLC1 | E11: ='Point List'!J8 -> 012294 | K11: =_xlfn.CONCAT(A11,",",B11,",",C11,",",D11,",",E11,",",F11,",",G11) -> Enable_Manual_Fan_Control,,BitAddress,PLC1,012294,, | O11: Enable Manual Fan Control,,BitAddress,PLC1,012294,,
A12: ='Point List'!C9 -> AVAILABLE | C12: ='Point List'!L9 -> BitAddress | D12: PLC1 | E12: ='Point List'!J9 -> 012295 | K12: =_xlfn.CONCAT(A12,",",B12,",",C12,",",D12,",",E12,",",F12,",",G12) -> AVAILABLE,,BitAddress,PLC1,012295,, | O12: AVAILABLE,,BitAddress,PLC1,012295,,
A13: ='Point List'!C10 -> Force_Fan_1_On_Off | C13: ='Point List'!L10 -> BitAddress | D13: PLC1 | E13: ='Point List'!J10 -> 012296 | K13: =_xlfn.CONCAT(A13,",",B13,",",C13,",",D13,",",E13,",",F13,",",G13) -> Force_Fan_1_On_Off,,BitAddress,PLC1,012296,, | O13: Force Fan 1 On/Off,,BitAddress,PLC1,012296,,
A14: ='Point List'!C11 -> Force_Fan_2_On_Off | C14: ='Point List'!L11 -> BitAddress | D14: PLC1 | E14: ='Point List'!J11 -> 012297 | K14: =_xlfn.CONCAT(A14,",",B14,",",C14,",",D14,",",E14,",",F14,",",G14) -> Force_Fan_2_On_Off,,BitAddress,PLC1,012297,, | O14: Force Fan 2 On/Off,,BitAddress,PLC1,012297,,
A15: ='Point List'!C12 -> Primary_Hydraulic_Fault_ACK | C15: ='Point List'!L12 -> BitAddress | D15: PLC1 | E15: ='Point List'!J12 -> 012298 | K15: =_xlfn.CONCAT(A15,",",B15,",",C15,",",D15,",",E15,",",F15,",",G15) -> Primary_Hydraulic_Fault_ACK,,BitAddress,PLC1,012298,, | O15: Primary Hydraulic Fault ACK,,BitAddress,PLC1,012298,,
A16: ='Point List'!C13 -> Secondary_Hydraulic_Fault_ACK | C16: ='Point List'!L13 -> BitAddress | D16: PLC1 | E16: ='Point List'!J13 -> 012299 | K16: =_xlfn.CONCAT(A16,",",B16,",",C16,",",D16,",",E16,",",F16,",",G16) -> Secondary_Hydraulic_Fault_ACK,,BitAddress,PLC1,012299,, | O16: Secondary Hydraulic Fault ACK,,BitAddress,PLC1,012299,,
A17: ='Point List'!C14 -> Enable_Pump_Cycling | C17: ='Point List'!L14 -> BitAddress | D17: PLC1 | E17: ='Point List'!J14 -> 012300 | K17: =_xlfn.CONCAT(A17,",",B17,",",C17,",",D17,",",E17,",",F17,",",G17) -> Enable_Pump_Cycling,,BitAddress,PLC1,012300,, | O17: Enable Pump Cycling,,BitAddress,PLC1,012300,,
... A19: ='Point List'!C16 -> Fault_ACK | C19: ='Point List'!L16 -> BitAddress | D19: PLC1 | E19: ='Point List'!J16 -> 012302 | K19: =_xlfn.CONCAT(A19,",",B19,",",C19,",",D19,",",E19,",",F19,",",G19) -> Fault_ACK,,BitAddress,PLC1,012302,, | O19: Fault ACK,,BitAddress,PLC1,012302,,
A20: ='Point List'!C19 -> System_On | C20: ='Point List'!L19 -> BitAddress | D20: PLC1 | E20: ='Point List'!J19 -> 012305 | K20: =_xlfn.CONCAT(A20,",",B20,",",C20,",",D20,",",E20,",",F20,",",G20) -> System_On,,BitAddress,PLC1,012305,, | O20: System On,,BitAddress,PLC1,012305,,
A21: ='Point List'!C20 -> System_Shutting_Down | C21: ='Point List'!L20 -> BitAddress | D21: PLC1 | E21: ='Point List'!J20 -> 012306 | K21: =_xlfn.CONCAT(A21,",",B21,",",C21,",",D21,",",E21,",",F21,",",G21) -> System_Shutting_Down,,BitAddress,PLC1,012306,, | O21: System Shutting Down,,BitAddress,PLC1,012306,,
A22: ='Point List'!C21 -> System_Initializing | C22: ='Point List'!L21 -> BitAddress | D22: PLC1 | E22: ='Point List'!J21 -> 012307 | K22: =_xlfn.CONCAT(A22,",",B22,",",C22,",",D22,",",E22,",",F22,",",G22) -> System_Initializing,,BitAddress,PLC1,012307,, | O22: System Initializing,,BitAddress,PLC1,012307,,
A23: ='Point List'!C22 -> System_Calibrating | C23: ='Point List'!L22 -> BitAddress | D23: PLC1 | E23: ='Point List'!J22 -> 012308 | K23: =_xlfn.CONCAT(A23,",",B23,",",C23,",",D23,",",E23,",",F23,",",G23) -> System_Calibrating,,BitAddress,PLC1,012308,, | O23: System Calibrating,,BitAddress,PLC1,012308,,
A24: ='Point List'!C23 -> Measured_Pump_Power | C24: ='Point List'!L23 -> WordAddress | D24: PLC1 | E24: ='Point List'!J23 -> 412557 | K24: =_xlfn.CONCAT(A24,",",B24,",",C24,",",D24,",",E24,",",F24,",",G24) -> Measured_Pump_Power,,WordAddress,PLC1,412557,, | O24: Measured Pump Power,,WordAddress,PLC1,412557,,
A25: ='Point List'!C24 -> MICT | C25: ='Point List'!L24 -> WordAddress | D25: PLC1 | E25: ='Point List'!J24 -> 412559 | K25: =_xlfn.CONCAT(A25,",",B25,",",C25,",",D25,",",E25,",",F25,",",G25) -> MICT,,WordAddress,PLC1,412559,, | O25: Measured Inlet Coolant Temperature,,WordAddress,PLC1,412559,,
A26: ='Point List'!C25 -> Measured_Conductivity | C26: ='Point List'!L25 -> WordAddress | D26: PLC1 | E26: ='Point List'!J25 -> 412561 | K26: =_xlfn.CONCAT(A26,",",B26,",",C26,",",D26,",",E26,",",F26,",",G26) -> Measured_Conductivity,,WordAddress,PLC1,412561,, | O26: Measured Conductivity,,WordAddress,PLC1,412561,,
A27: ='Point List'!C26 -> Measured_Flow | C27: ='Point List'!L26 -> WordAddress | D27: PLC1 | E27: ='Point List'!J26 -> 412563 | K27: =_xlfn.CONCAT(A27,",",B27,",",C27,",",D27,",",E27,",",F27,",",G27) -> Measured_Flow,,WordAddress,PLC1,412563,, | O27: Measured Flow,,WordAddress,PLC1,412563,,
A28: ='Point List'!C27 -> Valve_Open_Percentage | C28: ='Point List'!L27 -> WordAddress | D28: PLC1 | E28: ='Point List'!J27 -> 412565 | K28: =_xlfn.CONCAT(A28,",",B28,",",C28,",",D28,",",E28,",",F28,",",G28) -> Valve_Open_Percentage,,WordAddress,PLC1,412565,, | O28: Valve Open Percentage,,WordAddress,PLC1,412565,,
A29: ='Point List'!C28 -> Real_RTD_1_Signal | C29: ='Point List'!L28 -> WordAddress | D29: PLC1 | E29: ='Point List'!J28 -> 412567 | K29: =_xlfn.CONCAT(A29,",",B29,",",C29,",",D29,",",E29,",",F29,",",G29) -> Real_RTD_1_Signal,,WordAddress,PLC1,412567,, | O29: Real RTD 1 Signal,,WordAddress,PLC1,412567,,
A30: ='Point List'!C29 -> Real_RTD_2_Signal | C30: ='Point List'!L29 -> WordAddress | D30: PLC1 | E30: ='Point List'!J29 -> 412569 | K30: =_xlfn.CONCAT(A30,",",B30,",",C30,",",D30,",",E30,",",F30,",",G30) -> Real_RTD_2_Signal,,WordAddress,PLC1,412569,, | O30: Real RTD 2 Signal,,WordAddress,PLC1,412569,,
A31: ='Point List'!C30 -> Real_RTD_3_Signal | C31: ='Point List'!L30 -> WordAddress | D31: PLC1 | E31: ='Point List'!J30 -> 412571 | K31: =_xlfn.CONCAT(A31,",",B31,",",C31,",",D31,",",E31,",",F31,",",G31) -> Real_RTD_3_Signal,,WordAddress,PLC1,412571,, | O31: Real RTD 3 Signal,,WordAddress,PLC1,412571,,
A32: ='Point List'!C32 -> Measured_Valve_Position_ | C32: ='Point List'!L32 -> WordAddress | D32: PLC1 | E32: ='Point List'!J32 -> 412575 | K32: =_xlfn.CONCAT(A32,",",B32,",",C32,",",D32,",",E32,",",F32,",",G32) -> Measured_Valve_Position_,,WordAddress,PLC1,412575,, | O32: Measured Valve Position ,,WordAddress,PLC1,412575,,
A33: ='Point List'!C33 -> Debounced_Water_Level_Low_Signal | C33: ='Point List'!L33 -> WordAddress | D33: PLC1 | E33: ='Point List'!J33 -> 012309 | K33: =_xlfn.CONCAT(A33,",",B33,",",C33,",",D33,",",E33,",",F33,",",G33) -> Debounced_Water_Level_Low_Signal,,WordAddress,PLC1,012309,, | O33: Debounced Water Level Low Signal,,WordAddress,PLC1,012309,,
A34: ='Point List'!C38 -> Output_Water_Level_Low_Signal | C34: ='Point List'!L38 -> BitAddress | D34: PLC1 | E34: ='Point List'!J38 -> 012314 | K34: =_xlfn.CONCAT(A34,",",B34,",",C34,",",D34,",",E34,",",F34,",",G34) -> Output_Water_Level_Low_Signal,,BitAddress,PLC1,012314,, | O34: Output Water Level Low Signal,,BitAddress,PLC1,012314,,
A35: ='Point List'!C39 -> Output_Water_Level_Low_Low | C35: ='Point List'!L39 -> BitAddress | D35: PLC1 | E35: ='Point List'!J39 -> 012315 | K35: =_xlfn.CONCAT(A35,",",B35,",",C35,",",D35,",",E35,",",F35,",",G35) -> Output_Water_Level_Low_Low,,BitAddress,PLC1,012315,, | O35: Output Water Level Low Low Signal,,BitAddress,PLC1,012315,,
A36: ='Point List'!C40 -> Output_Pressure_Signal | C36: ='Point List'!L40 -> BitAddress | D36: PLC1 | E36: ='Point List'!J40 -> 012316 | K36: =_xlfn.CONCAT(A36,",",B36,",",C36,",",D36,",",E36,",",F36,",",G36) -> Output_Pressure_Signal,,BitAddress,PLC1,012316,, | O36: Output Pressure Signal,,BitAddress,PLC1,012316,,
A37: ='Point List'!C41 -> Output_Conductivity_Alarm_Signal | C37: ='Point List'!L41 -> BitAddress | D37: PLC1 | E37: ='Point List'!J41 -> 012317 | K37: =_xlfn.CONCAT(A37,",",B37,",",C37,",",D37,",",E37,",",F37,",",G37) -> Output_Conductivity_Alarm_Signal,,BitAddress,PLC1,012317,, | O37: Output Conductivity Alarm Signal,,BitAddress,PLC1,012317,,
A38: ='Point List'!C42 -> Output_Conductivity_Fault_Signal | C38: ='Point List'!L42 -> BitAddress | D38: PLC1 | E38: ='Point List'!J42 -> 012318 | K38: =_xlfn.CONCAT(A38,",",B38,",",C38,",",D38,",",E38,",",F38,",",G38) -> Output_Conductivity_Fault_Signal,,BitAddress,PLC1,012318,, | O38: Output Conductivity Fault Signal,,BitAddress,PLC1,012318,,
A39: ='Point List'!C45 -> Measured_Active_Pump__Voltage | C39: ='Point List'!L45 -> WordAddress | D39: PLC1 | E39: ='Point List'!J45 -> 412577 | K39: =_xlfn.CONCAT(A39,",",B39,",",C39,",",D39,",",E39,",",F39,",",G39) -> Measured_Active_Pump__Voltage,,WordAddress,PLC1,412577,, | O39: Measured Active Pump Voltage,,WordAddress,PLC1,412577,,
A40: ='Point List'!C46 -> Measured_Active_Pump__Current | C40: ='Point List'!L46 -> WordAddress | D40: PLC1 | E40: ='Point List'!J46 -> 412579 | K40: =_xlfn.CONCAT(A40,",",B40,",",C40,",",D40,",",E40,",",F40,",",G40) -> Measured_Active_Pump__Current,,WordAddress,PLC1,412579,, | O40: Measured Active Pump Current,,WordAddress,PLC1,412579,,
A41: ='Point List'!C49 -> Pump_1_Total_Hours | C41: ='Point List'!L49 -> WordAddress | D41: PLC1 | E41: ='Point List'!J49 -> 412455 | K41: =_xlfn.CONCAT(A41,",",B41,",",C41,",",D41,",",E41,",",F41,",",G41) -> Pump_1_Total_Hours,,WordAddress,PLC1,412455,, | O41: Pump 1 Total Hours,,WordAddress,PLC1,412455,,
A42: ='Point List'!C50 -> Pump_2_Total_Hours | C42: ='Point List'!L50 -> WordAddress | D42: PLC1 | E42: ='Point List'!J50 -> 412457 | K42: =_xlfn.CONCAT(A42,",",B42,",",C42,",",D42,",",E42,",",F42,",",G42) -> Pump_2_Total_Hours,,WordAddress,PLC1,412457,, | O42: Pump 2 Total Hours,,WordAddress,PLC1,412457,,
...
